Workbook

Sheet NhapLieu
A1: Lĩnh vực lớn | B1: Lĩnh vực con | C1: Công việc | D1: Sản phẩm | E1: Ngày giao | F1: Hạn hoàn thành | G1: Ngày hoàn thành | H1: Cán bộ tham mưu | I1: Cán bộ phụ trách
A2: I. Văn phòng - Tuyên giáo - Xây dựng Đoàn | B2: Văn phòng | C2: =Sheet1!F5 -> Kế hoạch thực hiện Nghị Quyết 59 của Bộ Chính trị | E2: 46113 | F2: 46122 | H2: Phan Xuân Tấn | I2: Trần Diệp Mỹ Dung
A3: I. Văn phòng - Tuyên giáo - Xây dựng Đoàn | B3: Văn phòng | C3: =Sheet1!F6 -> Báo cáo công tác Đoàn tháng 4 | E3: 46113 | F3: =Sheet1!I6 -> 46127 | H3: Bùi Thị Phượng | I3: Trần Diệp Mỹ Dung
A4: I. Văn phòng - Tuyên giáo - Xây dựng Đoàn | B4: Văn phòng | C4: =Sheet1!F7 -> Hướng dẫn xử lý văn bản bí mật nhà nước | E4: 46113 | F4: =Sheet1!I7 -> 46122 | H4: Phan Xuân Tấn | I4: Trần Diệp Mỹ Dung
A5: I. Văn phòng - Tuyên giáo - Xây dựng Đoàn | B5: Văn phòng | C5: =Sheet1!F8 -> Báo cáo điều tra cơ sở hành chính sự nghiệp năm 2026 | E5: 46113 | F5: =Sheet1!I8 -> 46122 | H5: Nguyễn Thị Thanh Hòa | I5: Trần Diệp Mỹ Dung
A6: I. Văn phòng - Tuyên giáo - Xây dựng Đoàn | B6: Văn phòng | C6: =Sheet1!F9 -> Tham mưu lịch công tác Tháng và Tuần của Thường trực | E6: 46113 | F6: 46142 | H6: Bùi Thị Phượng | I6: Trần Diệp Mỹ Dung
A7: I. Văn phòng - Tuyên giáo - Xây dựng Đoàn | B7: Văn phòng | C7: =Sheet1!F10 -> Thông báo kết quả giao ban tháng 4 | E7: 46113 | F7: 46122 | H7: Nguyễn Hồ Xuân Quang | I7: Trần Diệp Mỹ Dung
A8: I. Văn phòng - Tuyên giáo - Xây dựng Đoàn | B8: Văn phòng | C8: =Sheet1!F11 -> Tham mưu tài liệu họp Ban Thường vụ Tỉnh đoàn tháng 4 | E8: 46113 | F8: =Sheet1!I11 -> 46127 | H8: Nguyễn Hồ Xuân Quang | I8: Trần Diệp Mỹ Dung
A9: I. Văn phòng - Tuyên giáo - Xây dựng Đoàn | B9: Văn phòng | C9: =Sheet1!F12 -> Rà soát điều chỉnh Quy chế thi chi tiêu nội bộ tại Ban Công tác Đoàn và TTN | E9: 46113 | F9: 46127 | H9: Nguyễn Thị Thanh Hòa | I9: Trần Diệp Mỹ Dung
A10: I. Văn phòng - Tuyên giáo - Xây dựng Đoàn | B10: Văn phòng | C10: =Sheet1!F13 -> Báo cáo các nội dung liên quan phục vụ làm việc với Đoàn kiểm tra của Bộ Chính trị, Ban Bí thư | E10: 46113 | F10: =Sheet1!I13 -> 46120 | H10: Nguyễn Hồ Xuân Quang | I10: Trần Diệp Mỹ Dung
A11: I. Văn phòng - Tuyên giáo - Xây dựng Đoàn | B11: Văn phòng | C11: =Sheet1!F14 -> Quyết toán kinh phí hoạt động đã tổ chức | E11: 46113 | F11: =Sheet1!I14 -> 46132 | H11: Nguyễn Thị Thanh Hòa | I11: Trần Diệp Mỹ Dung
A12: I. Văn phòng - Tuyên giáo - Xây dựng Đoàn | B12: Văn phòng | C12: =Sheet1!F15 -> Phối hợp với văn phòng MTTQ bàn giao tài sản, nhà đất | E12: 46113 | F12: =Sheet1!I15 -> 46132 | H12: Nguyễn Hồ Xuân Quang | I12: Trần Diệp Mỹ Dung
A13: I. Văn phòng - Tuyên giáo - Xây dựng Đoàn | B13: Văn phòng | C13: =Sheet1!F16 -> Kê khai thông tin trên hệ thống Điều tra cơ sở hành chính, sự nghiệp của Bộ Nội vụ | E13: 46113 | F13: 46122 | H13: Nguyễn Hồ Xuân Quang | I13: Trần Diệp Mỹ Dung
A14: I. Văn phòng - Tuyên giáo - Xây dựng Đoàn | B14: Văn phòng | C14: =Sheet1!F17 -> Tham mưu các nội dung bàn giao tài sản và trụ sở cơ quan cũ cho cấp có thẩm quyền | E14: 46113 | F14: 46122 | H14: Nguyễn Hồ Xuân Quang | I14: Trần Diệp Mỹ Dung
A15: I. Văn phòng - Tuyên giáo - Xây dựng Đoàn | B15: Văn phòng | C15: =Sheet1!F18 -> Tiếp tục tham mưu giải quyết tồn động của các Tỉnh đoàn cũ (Dự án công viên Hoa Thanh niên; Sân bóng; Trung tâm SHDNTTN Bình Thuận | E15: 46113 | F15: 46142 | H15: Nguyễn Hồ Xuân Quang | I15: Trần Diệp Mỹ Dung
A16: I. Văn phòng - Tuyên giáo - Xây dựng Đoàn | B16: Văn phòng | C16: =Sheet1!F19 -> Rà soát kết quả thực hiện BTC quý 1 triển khai nhiệm vụ quý 2 | E16: 46113 | F16: 46142 | H16: Nguyễn Hồ Xuân Quang | I16: Trần Diệp Mỹ Dung
A17: I. Văn phòng - Tuyên giáo - Xây dựng Đoàn | B17: Văn phòng | C17: =Sheet1!F20 -> Lịch trực Ban nghĩ lễ Giỗ tổ Hùng Vương và 30/4 | E17: 46113 | F17: 46142 | H17: Phan Xuân Tấn | I17: Trần Diệp Mỹ Dung
A18: I. Văn phòng - Tuyên giáo - Xây dựng Đoàn | B18: Tuyên giáo | C18: =Sheet1!F21 -> Hướng dẫn tuyên truyền kỷ niệm 136 năm Ngày sinh Chỉ tịch Hồ Chí Minh | E18: 46113 | F18: =Sheet1!I21 -> 46132 | H18: Hồ Như Toán | I18: Trần Diệp Mỹ Dung
A19: I. Văn phòng - Tuyên giáo - Xây dựng Đoàn | B19: Tuyên giáo | C19: =Sheet1!F22 -> Báo cáo dư luận hàng tuần, tháng | E19: 46113 | F19: 46126 | H19: Đỗ Ngọc Hà | I19: Trần Diệp Mỹ Dung
A20: I. Văn phòng - Tuyên giáo - Xây dựng Đoàn | B20: Tuyên giáo | C20: =Sheet1!F23 -> KH, Thể lệ Cuộc thi trực tuyến tìm hiểu Nghị quyết Đại hội | E20: 46113 | F20: 46142 | H20: Đỗ Ngọc Hà | I20: Trần Việt Anh
A21: I. Văn phòng - Tuyên giáo - Xây dựng Đoàn | B21: Tuyên giáo | C21: =Sheet1!F24 -> QĐ trao giải Minigame tìm hiểu pháp luật về bầu cử | E21: 46113 | F21: 46142 | H21: Đỗ Ngọc Hà | I21: Trần Diệp Mỹ Dung
A22: I. Văn phòng - Tuyên giáo - Xây dựng Đoàn | B22: Tuyên giáo | C22: =Sheet1!F25 -> Các văn bản triển khai công tác 35 Tỉnh đoàn (văn bản mật, báo cáo định kỳ) | E22: 46113 | F22: 46142 | H22: Hồ Như Toán | I22: Trần Diệp Mỹ Dung
A23: I. Văn phòng - Tuyên giáo - Xây dựng Đoàn | B23: Tuyên giáo | C23: =Sheet1!F26 -> KH tổ chức Hành trình "Tuổi trẻ Lâm Đồng với biển đảo quê hương" năm 2026 | E23: 46113 | F23: =Sheet1!I26 -> 46122 | H23: Hồ Như Toán | I23: Trần Diệp Mỹ Dung
A24: I. Văn phòng - Tuyên giáo - Xây dựng Đoàn | B24: Tuyên giáo | C24: =Sheet1!F27 -> KH tổ chức Liên hoan tuyên truyền ca khúc cách mạng tỉnh Lâm Đồng năm 2026 | E24: 46113 | F24: =Sheet1!I27 -> 46122 | H24: Hồ Như Toán | I24: Trần Diệp Mỹ Dung
A25: I. Văn phòng - Tuyên giáo - Xây dựng Đoàn | B25: Tuyên giáo | C25: =Sheet1!F28 -> Báo cáo dư luận tháng 5 | E25: 46113 | F25: 46132 | H25: Đỗ Ngọc Hà | I25: Trần Diệp Mỹ Dung
A26: I. Văn phòng - Tuyên giáo - Xây dựng Đoàn | B26: Tuyên giáo | C26: =Sheet1!F29 -> Hướng dẫn tuyên truyền tháng 5 | E26: 46113 | F26: 46132 | H26: Đỗ Ngọc Hà | I26: Trần Diệp Mỹ Dung
A27: I. Văn phòng - Tuyên giáo - Xây dựng Đoàn | B27: Tuyên giáo | C27: =Sheet1!F30 -> CV giới thiệu nhân sự CTV Phòng chống tác hại của thuốc lá | E27: 46113 | F27: 46117 | H27: Hồ Như Toán | I27: Trần Diệp Mỹ Dung
A28: I. Văn phòng - Tuyên giáo - Xây dựng Đoàn | B28: Tuyên giáo | C28: =Sheet1!F31 -> KH tổ chức tuyên dương “Thanh niên tiên tiến làm theo lời Bác” nhân kỷ niệm 136 năm Ngày sinh Chủ tịch Hồ Chí Minh (19/5/1890 - 19/5/2026) | E28: 46113 | F28: 46127 | H28: Nguyễn Hồ Xuân Quang | I28: Trần Diệp Mỹ Dung
A29: I. Văn phòng - Tuyên giáo - Xây dựng Đoàn | B29: Tuyên giáo | C29: =Sheet1!F32 -> Kế hoạch tuyên truyền, vận động đoàn viên thanh niên và nhân dân tham gia bảo hiểm y tế toàn dân năm 2026 | E29: 46113 | F29: 46127 | H29: Nguyễn Hồ Xuân Quang | I29: Trần Diệp Mỹ Dung
A30: I. Văn phòng - Tuyên giáo - Xây dựng Đoàn | B30: Tuyên giáo | C30: =Sheet1!F33 -> Kế hoạch tuyên truyền phòng chống tác hại thuốc lá trong đoàn viên thanh niên năm 2026 | E30: 46113 | F30: =Sheet1!I33 -> 15/4/2026 | H30: Hồ Như Toán | I30: Trần Diệp Mỹ Dung
A31: I. Văn phòng - Tuyên giáo - Xây dựng Đoàn | B31: Tuyên giáo | C31: =Sheet1!F34 -> Lễ Phát động Cuộc thi trực tuyến tìm hiểu Nghị quyết Đại hội | E31: 46113 | F31: 46118 | H31: Đỗ Ngọc Hà | I31: Trần Việt Anh
A32: I. Văn phòng - Tuyên giáo - Xây dựng Đoàn | B32: Tuyên giáo | C32: =Sheet1!F35 -> Trao giải Minigame tìm hiểu pháp luật về bầu cử | E32: 46113 | F32: 46129 | H32: Đỗ Ngọc Hà | I32: Trần Diệp Mỹ Dung
A33: I. Văn phòng - Tuyên giáo - Xây dựng Đoàn | B33: Tuyên giáo | C33: =Sheet1!F36 -> Tiếp tục ôn đốc đăng tải triển khai Đề án Những câu chuyện thời hoa lửa | E33: 46113 | F33: 46142 | H33: Đỗ Ngọc Hà | I33: Trần Diệp Mỹ Dung
A34: I. Văn phòng - Tuyên giáo - Xây dựng Đoàn | B34: Tuyên giáo | C34: =Sheet1!F37 -> Tham mưu các nội dung liên quan đến Lễ hội Giỗ tổ Hùng Vương | E34: 46113 | F34: 46138 | H34: Đỗ Ngọc Hà | I34: Trần Diệp Mỹ Dung
A35: I. Văn phòng - Tuyên giáo - Xây dựng Đoàn | B35: Tuyên giáo | C35: =Sheet1!F38 -> Tổ chức Chương trình sinh hoạt chính trị nhân kỷ niệm 51 năm Giải phóng miền Nam, thống nhất đất nước ngày (30/4/1975 - 30/4/2026) | E35: 46113 | F35: 46122 | H35: Hồ Như Toán | I35: Trần Diệp Mỹ Dung
A36: I. Văn phòng - Tuyên giáo - Xây dựng Đoàn | B36: Tuyên giáo | C36: =Sheet1!F39 -> Tham mưu gửi ấn phẩm phục vụ biên soạn các ấn phẩm chào mừng Đại hội Đoàn toàn quốc lần thứ XII | E36: 46113 | F36: 46129 | H36: Đỗ Ngọc Hà | I36: Trần Diệp Mỹ Dung
A37: I. Văn phòng - Tuyên giáo - Xây dựng Đoàn | B37: Tuyên giáo | C37: =Sheet1!F40 -> Tuyên truyền kịp thời các hoạt động tập trung cấp tỉnh trong tháng | E37: 46113 | F37: 46142 | H37: Đỗ Ngọc Hà | I37: Trần Diệp Mỹ Dung
A38: I. Văn phòng - Tuyên giáo - Xây dựng Đoàn | B38: Xây dựng Đoàn | C38: =Sheet1!F41 -> Kế hoạch rà soát quy hoạch các chức danh chủ chốt của Đoàn năm 2026 | E38: 46113 | F38: 46122 | H38: Nguyễn Hồ Xuân Quang | I38: Trần Diệp Mỹ Dung
A39: I. Văn phòng - Tuyên giáo - Xây dựng Đoàn | B39: Xây dựng Đoàn | C39: =Sheet1!F42 -> CV góp ý dự thảo hướng dẫn quy trình thủ tục kiện toàn bổ sung nhân sự cấp tỉnh | E39: 46113 | F39: 46114 | H39: Võ Văn Đồng | I39: Trần Việt Anh
A40: I. Văn phòng - Tuyên giáo - Xây dựng Đoàn | B40: Xây dựng Đoàn | C40: =Sheet1!F43 -> CV góp ý dự thảo Hướng dẫn một số vấn đề cụ thể thi hành Điều lệ Đảng | E40: 46113 | F40: 46116 | H40: Nguyễn Hồ Xuân Quang | I40: Trần Việt Anh
...

Sheet Sheet1
B3: TT | D3: SL CÔNG VIỆC | F3: NỘI DUNG CÔNG VIỆC | G3: TT PHỤ TRÁCH | H3: CB THAM MƯU | I3: THỜI GIAN HOÀN THÀNH
B4: I. Văn phòng - Tuyên giáo - Xây dựng Đoàn
B5: 1 | C5: Văn phòng | D5: Văn bản | E5: 1 | F5: Kế hoạch thực hiện Nghị Quyết 59 của Bộ Chính trị | G5: Đ/c Dung | H5: Đ/c Tấn | I5: 46299 | J5: 1
E6: 2 | F6: Báo cáo công tác Đoàn tháng 4 | H6: Đ/c Phượng | I6: 46127 | J6: 2
E7: 3 | F7: Hướng dẫn xử lý văn bản bí mật nhà nước | H7: Đ/c Tấn | I7: 46122 | J7: 3
E8: 4 | F8: Báo cáo điều tra cơ sở hành chính sự nghiệp năm 2026 | H8: Đ/c Hòa | I8: 46122 | J8: 4
E9: 5 | F9: Tham mưu lịch công tác Tháng và Tuần của Thường trực | H9: Đ/c Cầm, Phượng | I9: hàng tuần | J9: 5
E10: 6 | F10: Thông báo kết quả giao ban tháng 4 | H10: Đ/c Quang | I10: 10/4/2026 | J10: 6
E11: 7 | F11: Tham mưu tài liệu họp Ban Thường vụ Tỉnh đoàn tháng 4 | H11: Đ/c Quang | I11: 46127 | J11: 7
E12: 9 | F12: Rà soát điều chỉnh Quy chế thi chi tiêu nội bộ tại Ban Công tác Đoàn và TTN | H12: Đ/c Hòa | I12: trước 15/4/2026 | J12: 9
E13: 10 | F13: Báo cáo các nội dung liên quan phục vụ làm việc với Đoàn kiểm tra của Bộ Chính trị, Ban Bí thư | H13: Đ/c Xuân Quang | I13: 46120 | J13: 10
D14: Công việc | E14: 1 | F14: Quyết toán kinh phí hoạt động đã tổ chức | G14: Đ/c Dung | H14: Đ/c Hòa | I14: 46132 | J14: 11
E15: 2 | F15: Phối hợp với văn phòng MTTQ bàn giao tài sản, nhà đất | H15: Đ/c Xuân Quang | I15: 46132 | J15: 12
E16: 3 | F16: Kê khai thông tin trên hệ thống Điều tra cơ sở hành chính, sự nghiệp của Bộ Nội vụ | H16: Đ/c Xuân Quang | I16: 46299 | J16: 13
E17: 4 | F17: Tham mưu các nội dung bàn giao tài sản và trụ sở cơ quan cũ cho cấp có thẩm quyền | H17: Đ/c Xuân Quang | I17: 46299 | J17: 14
E18: 5 | F18: Tiếp tục tham mưu giải quyết tồn động của các Tỉnh đoàn cũ (Dự án công viên Hoa Thanh niên; Sân bóng; Trung tâm SHDNTTN Bình Thuận | H18: Đ/c Tấn | I18: 31/4/2026 | J18: 15
E19: 6 | F19: Rà soát kết quả thực hiện BTC quý 1 triển khai nhiệm vụ quý 2 | H19: Đ/c Xuân Quang | I19: 31/4/2026 | J19: 16
E20: 7 | F20: Lịch trực Ban nghĩ lễ Giỗ tổ Hùng Vương và 30/4 | H20: Đ/c Tấn | I20: 31/4/2026 | J20: 17
B21: 2 | C21: Tuyên giáo | D21: Văn bản | E21: 1 | F21: Hướng dẫn tuyên truyền kỷ niệm 136 năm Ngày sinh Chỉ tịch Hồ Chí Minh | G21: Đ/c Dung | H21: Đc Toán | I21: 46132 | J21: 18
E22: 3 | F22: Báo cáo dư luận hàng tuần, tháng | G22: Đ/c Dung | H22: Đ/c Hà | I22: Trong tháng 4 | J22: 20
E23: 4 | F23: KH, Thể lệ Cuộc thi trực tuyến tìm hiểu Nghị quyết Đại hội | G23: Đ/c Việt Anh | H23: Đ/c Hà | I23: Trong tháng 4 | J23: 21
E24: 5 | F24: QĐ trao giải Minigame tìm hiểu pháp luật về bầu cử | G24: Đ/c Dung | H24: Đ/c Hà | I24: Trong tháng 4 | J24: 22
E25: 6 | F25: Các văn bản triển khai công tác 35 Tỉnh đoàn (văn bản mật, báo cáo định kỳ) | G25: Đ/c Dung | H25: Đ/c Toán | I25: Trong tháng | J25: 23
E26: 7 | F26: KH tổ chức Hành trình "Tuổi trẻ Lâm Đồng với biển đảo quê hương" năm 2026 | G26: Đ/c Dung | H26: Đ/c Toán | I26: 46122 | J26: 24
E27: 8 | F27: KH tổ chức Liên hoan tuyên truyền ca khúc cách mạng tỉnh Lâm Đồng năm 2026 | G27: Đ/c Dung | H27: Đ/c Toán | I27: 46122 | J27: 25
E28: 9 | F28: Báo cáo dư luận tháng 5 | G28: Đ/c Dung | H28: Đ/c Hà | I28: trước 25/4 | J28: 26
E29: 10 | F29: Hướng dẫn tuyên truyền tháng 5 | G29: Đ/c Dung | H29: Đ/c Hà | I29: trước 25/4 | J29: 27
E30: 11 | F30: CV giới thiệu nhân sự CTV Phòng chống tác hại của thuốc lá | G30: Đ/c Dung | H30: Đ/c Toán | I30: trước 25/4 | J30: 28
E31: 12 | F31: KH tổ chức tuyên dương “Thanh niên tiên tiến làm theo lời Bác” nhân kỷ niệm 136 năm Ngày sinh Chủ tịch Hồ Chí Minh (19/5/1890 - 19/5/2026) | G31: Đ/c Dung | H31: Đ/c Xuân Quang | I31: 20/4/2026 | J31: 29
E32: 13 | F32: Kế hoạch tuyên truyền, vận động đoàn viên thanh niên và nhân dân tham gia bảo hiểm y tế toàn dân năm 2026 | G32: Đ/c Dung | H32: Đ/c Xuân Quang | I32: 20/4/2026 | J32: 30
E33: 14 | F33: Kế hoạch tuyên truyền phòng chống tác hại thuốc lá trong đoàn viên thanh niên năm 2026 | G33: Đ/c Dung | H33: Đ/c Toán | I33: 15/4/2026 | J33: 31
D34: Công việc | E34: 1 | F34: Lễ Phát động Cuộc thi trực tuyến tìm hiểu Nghị quyết Đại hội | G34: Đ/c Dung | H34: Đ/c Hà | I34: Trong tháng 4 | J34: 32
E35: 2 | F35: Trao giải Minigame tìm hiểu pháp luật về bầu cử | G35: Đ/c Dung | H35: Đ/c Hà | I35: Trong tháng 4 | J35: 33
E36: 3 | F36: Tiếp tục ôn đốc đăng tải triển khai Đề án Những câu chuyện thời hoa lửa | G36: Đ/c Dung | H36: Đ/c Hà | I36: Trong tháng 4 | J36: 34
E37: 4 | F37: Tham mưu các nội dung liên quan đến Lễ hội Giỗ tổ Hùng Vương | G37: Đ/c Dung | H37: Đ/c Hà | I37: Trong tháng 4 | J37: 35
E38: 5 | F38: Tổ chức Chương trình sinh hoạt chính trị nhân kỷ niệm 51 năm Giải phóng miền Nam, thống nhất đất nước ngày (30/4/1975 - 30/4/2026) | G38: Đ/c Dung | H38: Đ/c Toán | I38: Trong tháng | J38: 36
F39: Tham mưu gửi ấn phẩm phục vụ biên soạn các ấn phẩm chào mừng Đại hội Đoàn toàn quốc lần thứ XII | G39: Đ/c Dung | H39: Đ/c Hà | I39: Trước 17/4/2026 | J39: 37
E40: 6 | F40: Tuyên truyền kịp thời các hoạt động tập trung cấp tỉnh trong tháng | G40: Đ/c Dung | H40: Đ/c Hà,Toán | I40: Trong tháng | J40: 38
B41: 3 | C41: Xây dựng Đoàn | D41: Văn bản | E41: 1 | F41: Kế hoạch rà soát quy hoạch các chức danh chủ chốt của Đoàn năm 2026 | G41: Đ/c Dung | H41: Đ/c Xuân Quang | I41: 10/4/2026 | J41: 39
E42: 2 | F42: CV góp ý dự thảo hướng dẫn quy trình thủ tục kiện toàn bổ sung nhân sự cấp tỉnh | G42: Đ/c Việt Anh | H42: Đ/c Đồng | I42: 02/4/2026 | J42: 40
...

Sheet DanhMuc
A1: I. Văn phòng - Tuyên giáo - Xây dựng Đoàn | B1: Văn phòng | C1: Trương Minh Quang | D1: 1
A2: II. Phong trào - Hội LHTN | B2: Tuyên giáo | C2: Trần Diệp Mỹ Dung | D2: 2
A3: III. Trường học - Hội Sinh viên | B3: Xây dựng Đoàn | C3: H' Hồng | D3: 3
B4: Phong trào | C4: Đoàn Minh Tâm | D4: 4
B5: Hội LHTN | C5: Trần Việt Anh | D5: 5
B6: Trường học | C6: Nguyễn Hồ Xuân Quang | D6: 6
B7: Hội Sinh viên | C7: Nguyễn Trọng Tùng | D7: 7
C8: Đào Hùng | D8: 8
C9: Châu Yến Phi | D9: 9
C10: Bùi Thị Phượng | D10: 10
C11: Hồ Như Toán | D11: 11
C12: Trịnh Thị Vỹ Cầm | D12: 12
C13: Nguyễn Linh Phương | D13: 13
C14: Võ Văn Đồng | D14: 14
C15: Nguyễn Nam Sơn | D15: 15
C16: Nguyễn Thị Thanh Hòa | D16: 16
C17: Phan Xuân Tấn | D17: 17
C18: Nguyễn Đình Hưng Thịnh | D18: 18
C19: Đỗ Ngọc Hà | D19: 19
... C21: Nguyễn Trọng Văn | D21: 21
